Workbook

Sheet groupe
A1: ETU003275 | B1: Manampy
A2: ETU003342 | B2: Antonio
A3: ETU003344 | B3: Eddou
A4: ETU003389 | B4: Ewan

Sheet liste des taches
A1: Ligne | B1: Catégorie | C1: Module | D1: Page | E1: Taches | F1: Type | G1: Qui | H1: Estimation | I1: Temps passé | J1: Reste à faire | K1: Avancement
A2: 1 | B2: API - Auth | C2: Authentification | D2: Inscription | E2: Endpoint POST /auth/register | F2: Affichage | G2: ETU003275 | H2: 30 | I2: =detail_avancement!B2 -> 30 | J2: =H2-I2 -> 0 | K2: =(I2/(I2+J2)) -> 1
A3: 2 | B3: API - Auth | C3: Authentification | D3: Inscription | E3: Validation données entrée | F3: Métier | G3: ETU003342 | H3: 30 | I3: =detail_avancement!B3 -> 30 | J3: =H3-I3 -> 0 | K3: =(I3/(I3+J3)) -> 1
A4: 3 | B4: API - Auth | C4: Authentification | D4: Inscription | E4: Enregistrement Firebase/Postgres | F4: Intégration | G4: ETU003344 | H4: 40 | I4: =detail_avancement!B4 -> 40 | J4: =H4-I4 -> 0 | K4: =(I4/(I4+J4)) -> 1
A5: 4 | B5: API - Auth | C5: Authentification | D5: Connexion | E5: Endpoint POST /auth/login | F5: Affichage | G5: ETU003389 | H5: 30 | I5: =detail_avancement!B5 -> 30 | J5: =H5-I5 -> 0 | K5: =(I5/(I5+J5)) -> 1
A6: 5 | B6: API - Auth | C6: Authentification | D6: Connexion | E6: Vérification identifiants | F6: Métier | G6: ETU003275 | H6: 30 | I6: =detail_avancement!B6 -> 30 | J6: =H6-I6 -> 0 | K6: =(I6/(I6+J6)) -> 1
A7: 6 | B7: API - Auth | C7: Authentification | D7: Connexion | E7: Génération token JWT/session | F7: Intégration | G7: ETU003342 | H7: 40 | I7: =detail_avancement!B7 -> 40 | J7: =H7-I7 -> 0 | K7: =(I7/(I7+J7)) -> 1
A8: 7 | B8: API - User | C8: Gestion Utilisateurs | D8: Profil Utilisateur | E8: Endpoint GET /users/me | F8: Affichage | G8: ETU003344 | H8: 30 | I8: =detail_avancement!B8 -> 30 | J8: =H8-I8 -> 0 | K8: =(I8/(I8+J8)) -> 1
A9: 8 | B9: API - User | C9: Gestion Utilisateurs | D9: Profil Utilisateur | E9: Endpoint PUT /users/me | F9: Affichage | G9: ETU003389 | H9: 30 | I9: =detail_avancement!B9 -> 30 | J9: =H9-I9 -> 0 | K9: =(I9/(I9+J9)) -> 1
A10: 9 | B10: API - User | C10: Gestion Utilisateurs | D10: Profil Utilisateur | E10: Validation données mise à jour | F10: Métier | G10: ETU003275 | H10: 30 | I10: =detail_avancement!B10 -> 30 | J10: =H10-I10 -> 0 | K10: =(I10/(I10+J10)) -> 1
A11: 10 | B11: API - User | C11: Gestion Utilisateurs | D11: Profil Utilisateur | E11: Synchronisation Firebase/Postgres | F11: Intégration | G11: ETU003342 | H11: 40 | I11: =detail_avancement!B11 -> 40 | J11: =H11-I11 -> 0 | K11: =(I11/(I11+J11)) -> 1
A12: 11 | B12: Logique métier | C12: Gestion Connexion | D12: Gestion Réseau | E12: Détection statut réseau (online/offline) | F12: Métier | G12: ETU003344 | H12: 30 | I12: =detail_avancement!B12 -> 30 | J12: =H12-I12 -> 0 | K12: =(I12/(I12+J12)) -> 1
A13: 12 | B13: Logique métier | C13: Gestion Connexion | D13: Gestion Réseau | E13: Stratégie bascule entre Firebase / Postgres | F13: Métier | G13: ETU003389 | H13: 30 | I13: =detail_avancement!B13 -> 30 | J13: =H13-I13 -> 0 | K13: =(I13/(I13+J13)) -> 1
... A112: 111 | B112: Mobile | C112: Localisation Mobile | D112: Permissions GPS | E112: Gestion permissions GPS (mobile) | F112: Intégration | G112: ETU003344 | H112: 25 | I112: =detail_avancement!B112 -> 0 | J112: =H112-I112 -> 25 | K112: =(I112/(I112+J112)) -> 0

Sheet detail_avancement
A1: Ligne | B1: Total | C1: 26/1 | D1: 27/1 | E1: 28/1
A2: 1 | B2: =SUM(C2:E2) -> 30 | C2: 30
A3: 2 | B3: =SUM(C3:E3) -> 30 | C3: 30
A4: 3 | B4: =SUM(C4:E4) -> 40 | C4: 40
A5: 4 | B5: =SUM(C5:E5) -> 30 | C5: 30
A6: 5 | B6: =SUM(C6:E6) -> 30 | C6: 30
A7: 6 | B7: =SUM(C7:E7) -> 40 | C7: 40
A8: 7 | B8: =SUM(C8:E8) -> 30 | C8: 30
A9: 8 | B9: =SUM(C9:E9) -> 30 | C9: 30
A10: 9 | B10: =SUM(C10:E10) -> 30 | C10: 30
A11: 10 | B11: =SUM(C11:E11) -> 40 | C11: 40
A12: 11 | B12: =SUM(C12:E12) -> 30 | C12: 30
A13: 12 | B13: =SUM(C13:E13) -> 30 | C13: 30
... A21: 20 | B21: =SUM(C21:E21) -> 0 | C21: 0
A22: 21 | B22: =SUM(C22:E22) -> 30 | C22: 0 | D22: 30
A23: 22 | B23: =SUM(C23:E23) -> 30 | C23: 0 | D23: 30
A24: 23 | B24: =SUM(C24:E24) -> 0 | C24: 0
A25: 24 | B25: =SUM(C25:E25) -> 0 | C25: 0
A26: 25 | B26: =SUM(C26:E26) -> 25 | C26: 0 | D26: 25
A27: 26 | B27: =SUM(C27:E27) -> 25 | C27: 0 | D27: 25
A28: 27 | B28: =SUM(C28:E28) -> 0 | C28: 0
A29: 28 | B29: =SUM(C29:E29) -> 30 | C29: 0 | D29: 30
A30: 29 | B30: =SUM(C30:E30) -> 0 | C30: 0
A31: 30 | B31: =SUM(C31:E31) -> 0 | C31: 0
A32: 31 | B32: =SUM(C32:E32) -> 0 | C32: 0
A33: 32 | B33: =SUM(C33:E33) -> 25 | C33: 0 | D33: 25
A34: 33 | B34: =SUM(C34:E34) -> 0 | C34: 0
A35: 34 | B35: =SUM(C35:E35) -> 0 | C35: 0
A36: 35 | B36: =SUM(C36:E36) -> 0 | C36: 0
A37: 36 | B37: =SUM(C37:E37) -> 0 | C37: 0
A38: 37 | B38: =SUM(C38:E38) -> 25 | C38: 25
A39: 38 | B39: =SUM(C39:E39) -> 30 | C39: 0 | D39: 30
A40: 39 | B40: =SUM(C40:E40) -> 25 | C40: 25
A41: 40 | B41: =SUM(C41:E41) -> 0 | C41: 0
A42: 41 | B42: =SUM(C42:E42) -> 0 | C42: 0
A43: 42 | B43: =SUM(C43:E43) -> 0 | C43: 0
A44: 43 | B44: =SUM(C44:E44) -> 0 | C44: 0
A45: 44 | B45: =SUM(C45:E45) -> 0 | C45: 0
A46: 45 | B46: =SUM(C46:E46) -> 0 | C46: 0
A47: 46 | B47: =SUM(C47:E47) -> 0 | C47: 0
...

Sheet avancement
A1: estimation total | B1: temps passé total | C1: reste à faire total | D1: avancement | E1: dépassement
A2: =SUM('liste des taches'!H:H) -> 3240 | B2: =SUM('liste des taches'!I:I) -> 1150 | C2: =SUM('liste des taches'!J:J) -> 2090 | D2: =(B2/(B2+C2)) -> 0.35493827 | E2: =((B2+C2)-A2)/A2 -> 0
C3: =C2/60 -> 34.833333 | D3: heure

Sheet Recap
A12: Avancement | B12: =avancement!D2 -> 0.35493827
